Traceback (most recent call last):
  File "/Users/hongtaoh/anaconda3/envs/bayes/lib/python3.8/site-packages/jupyter_cache/executors/utils.py", line 58, in single_nb_execution
    executenb(
  File "/Users/hongtaoh/anaconda3/envs/bayes/lib/python3.8/site-packages/nbclient/client.py", line 1305, in execute
    return NotebookClient(nb=nb, resources=resources, km=km, **kwargs).execute()
  File "/Users/hongtaoh/anaconda3/envs/bayes/lib/python3.8/site-packages/jupyter_core/utils/__init__.py", line 165, in wrapped
    return loop.run_until_complete(inner)
  File "/Users/hongtaoh/anaconda3/envs/bayes/lib/python3.8/asyncio/base_events.py", line 616, in run_until_complete
    return future.result()
  File "/Users/hongtaoh/anaconda3/envs/bayes/lib/python3.8/site-packages/nbclient/client.py", line 705, in async_execute
    await self.async_execute_cell(
  File "/Users/hongtaoh/anaconda3/envs/bayes/lib/python3.8/site-packages/nbclient/client.py", line 1058, in async_execute_cell
    await self._check_raise_for_error(cell, cell_index, exec_reply)
  File "/Users/hongtaoh/anaconda3/envs/bayes/lib/python3.8/site-packages/nbclient/client.py", line 914, in _check_raise_for_error
    raise CellExecutionError.from_cell_and_msg(cell, exec_reply_content)
nbclient.exceptions.CellExecutionError: An error occurred while executing the following cell:
------------------
num_biomarkers = len(pdata.Biomarker.unique())
num_iterations = 1000
best_order, best_likelihood = metropolis_hastings(pdata, num_biomarkers, num_iterations)
best_order
------------------

----- stderr -----
/var/folders/wx/xz5y_06d15q5pgl_mhv76c8r0000gn/T/ipykernel_75813/3826826747.py:27: RuntimeWarning: invalid value encountered in double_scalars
  ratio = likelihood/best_likelihood
------------------

[0;31m---------------------------------------------------------------------------[0m
[0;31mTypeError[0m                                 Traceback (most recent call last)
Cell [0;32mIn[15], line 3[0m
[1;32m      1[0m num_biomarkers [38;5;241m=[39m [38;5;28mlen[39m(pdata[38;5;241m.[39mBiomarker[38;5;241m.[39munique())
[1;32m      2[0m num_iterations [38;5;241m=[39m [38;5;241m1000[39m
[0;32m----> 3[0m best_order, best_likelihood [38;5;241m=[39m [43mmetropolis_hastings[49m[43m([49m[43mpdata[49m[43m,[49m[43m [49m[43mnum_biomarkers[49m[43m,[49m[43m [49m[43mnum_iterations[49m[43m)[49m
[1;32m      4[0m best_order

Cell [0;32mIn[13], line 28[0m, in [0;36mmetropolis_hastings[0;34m(pdata, num_biomarkers, iterations)[0m
[1;32m     26[0m [38;5;28;01melse[39;00m: 
[1;32m     27[0m     ratio [38;5;241m=[39m likelihood[38;5;241m/[39mbest_likelihood
[0;32m---> 28[0m     random_number [38;5;241m=[39m [43mnp[49m[38;5;241;43m.[39;49m[43mrandom[49m[43m([49m[38;5;241;43m0[39;49m[43m,[49m[38;5;241;43m1[39;49m[43m)[49m
[1;32m     29[0m     [38;5;28;01mif[39;00m random_number [38;5;241m<[39m ratio:
[1;32m     30[0m         best_likelihood [38;5;241m=[39m likelihood

[0;31mTypeError[0m: 'module' object is not callable

